<?xml version="1.0" ?>
<robot name="proto_plate" xmlns:xacro="http://www.ros.org/wiki/xacro">

<xacro:include filename="$(find proto_plate_description)/urdf/materials.xacro" />
<xacro:include filename="$(find proto_plate_description)/urdf/proto_plate.trans" />
<xacro:include filename="$(find proto_plate_description)/urdf/proto_plate.gazebo" />
<link name="base_link">
  <inertial>
    <origin rpy="0 0 0" xyz="-0.0006244704600712999 -7.232694834270641e-06 0.0359784642751064"/>
    <mass value="0.26119687495403604"/>
    <inertia ixx="0.000747" ixy="0.0" ixz="5e-06" iyy="0.000751" iyz="-0.0" izz="0.001259"/>
  </inertial>
  <visual>
    <origin rpy="0 0 0" xyz="0 0 0"/>
    <geometry>
      <mesh filename="package://proto_plate_description/meshes/base_link.stl" scale="0.001 0.001 0.001"/>
    </geometry>
    <material name="silver"/>
  </visual>
  <collision>
    <origin rpy="0 0 0" xyz="0 0 0"/>
    <geometry>
      <mesh filename="package://proto_plate_description/meshes/base_link.stl" scale="0.001 0.001 0.001"/>
    </geometry>
  </collision>
</link>

<link name="shoulder_link_1_1">
  <inertial>
    <origin rpy="0 0 0" xyz="-0.0009079559657418734 -0.0015133217215439793 0.033919147547046044"/>
    <mass value="0.18619075805658886"/>
    <inertia ixx="8.7e-05" ixy="-3e-06" ixz="-2e-06" iyy="0.000124" iyz="1e-06" izz="0.000123"/>
  </inertial>
  <visual>
    <origin rpy="0 0 0" xyz="-0.0 -0.0 -0.07025"/>
    <geometry>
      <mesh filename="package://proto_plate_description/meshes/shoulder_link_1_1.stl" scale="0.001 0.001 0.001"/>
    </geometry>
    <material name="silver"/>
  </visual>
  <collision>
    <origin rpy="0 0 0" xyz="-0.0 -0.0 -0.07025"/>
    <geometry>
      <mesh filename="package://proto_plate_description/meshes/shoulder_link_1_1.stl" scale="0.001 0.001 0.001"/>
    </geometry>
  </collision>
</link>

<link name="upper_link_1">
  <inertial>
    <origin rpy="0 0 0" xyz="0.061931198177829286 -0.048971978432293437 0.028124060023449332"/>
    <mass value="0.30108115363872223"/>
    <inertia ixx="0.000388" ixy="8e-06" ixz="-1.4e-05" iyy="0.000341" iyz="9e-05" izz="0.000494"/>
  </inertial>
  <visual>
    <origin rpy="0 0 0" xyz="0.044191 0.011841 -0.10385"/>
    <geometry>
      <mesh filename="package://proto_plate_description/meshes/upper_link_1.stl" scale="0.001 0.001 0.001"/>
    </geometry>
    <material name="silver"/>
  </visual>
  <collision>
    <origin rpy="0 0 0" xyz="0.044191 0.011841 -0.10385"/>
    <geometry>
      <mesh filename="package://proto_plate_description/meshes/upper_link_1.stl" scale="0.001 0.001 0.001"/>
    </geometry>
  </collision>
</link>

<link name="lower_link_1_1">
  <inertial>
    <origin rpy="0 0 0" xyz="-0.04514584214050543 -0.011083808837687545 0.07125808341355"/>
    <mass value="0.2304261792350949"/>
    <inertia ixx="0.000386" ixy="-3.4e-05" ixz="-9e-06" iyy="0.000502" iyz="-1e-05" izz="0.000242"/>
  </inertial>
  <visual>
    <origin rpy="0 0 0" xyz="-0.065307 0.066961 -0.139044"/>
    <geometry>
      <mesh filename="package://proto_plate_description/meshes/lower_link_1_1.stl" scale="0.001 0.001 0.001"/>
    </geometry>
    <material name="silver"/>
  </visual>
  <collision>
    <origin rpy="0 0 0" xyz="-0.065307 0.066961 -0.139044"/>
    <geometry>
      <mesh filename="package://proto_plate_description/meshes/lower_link_1_1.stl" scale="0.001 0.001 0.001"/>
    </geometry>
  </collision>
</link>

<link name="shoulder_link_2_1">
  <inertial>
    <origin rpy="0 0 0" xyz="-0.0016970413627136992 0.0004848743008749462 0.03391918641583466"/>
    <mass value="0.18619075805658886"/>
    <inertia ixx="0.00012" ixy="1.2e-05" ixz="1e-06" iyy="9.1e-05" iyz="2e-06" izz="0.000123"/>
  </inertial>
  <visual>
    <origin rpy="0 0 0" xyz="-0.021116 0.078802 -0.249294"/>
    <geometry>
      <mesh filename="package://proto_plate_description/meshes/shoulder_link_2_1.stl" scale="0.001 0.001 0.001"/>
    </geometry>
    <material name="silver"/>
  </visual>
  <collision>
    <origin rpy="0 0 0" xyz="-0.021116 0.078802 -0.249294"/>
    <geometry>
      <mesh filename="package://proto_plate_description/meshes/shoulder_link_2_1.stl" scale="0.001 0.001 0.001"/>
    </geometry>
  </collision>
</link>

<link name="lower_link_2_1">
  <inertial>
    <origin rpy="0 0 0" xyz="-0.03305000853986549 -0.07274685301709907 0.02922780640062922"/>
    <mass value="0.2304261792350949"/>
    <inertia ixx="0.000299" ixy="-3.5e-05" ixz="8.7e-05" iyy="0.000363" iyz="4.5e-05" izz="0.000468"/>
  </inertial>
  <visual>
    <origin rpy="0 0 0" xyz="0.001759 0.039182 -0.282894"/>
    <geometry>
      <mesh filename="package://proto_plate_description/meshes/lower_link_2_1.stl" scale="0.001 0.001 0.001"/>
    </geometry>
    <material name="silver"/>
  </visual>
  <collision>
    <origin rpy="0 0 0" xyz="0.001759 0.039182 -0.282894"/>
    <geometry>
      <mesh filename="package://proto_plate_description/meshes/lower_link_2_1.stl" scale="0.001 0.001 0.001"/>
    </geometry>
  </collision>
</link>

<link name="Plate_link_simp_v1_1">
  <inertial>
    <origin rpy="0 0 0" xyz="-0.007563488333636778 -0.005561466402512094 8.940003590274248e-05"/>
    <mass value="0.014207091734286338"/>
    <inertia ixx="4e-06" ixy="1e-06" ixz="-1e-06" iyy="3e-06" iyz="-0.0" izz="3e-06"/>
  </inertial>
  <visual>
    <origin rpy="0 0 0" xyz="0.065418 0.128763 -0.329488"/>
    <geometry>
      <mesh filename="package://proto_plate_description/meshes/Plate_link_simp_v1_1.stl" scale="0.001 0.001 0.001"/>
    </geometry>
    <material name="silver"/>
  </visual>
  <collision>
    <origin rpy="0 0 0" xyz="0.065418 0.128763 -0.329488"/>
    <geometry>
      <mesh filename="package://proto_plate_description/meshes/Plate_link_simp_v1_1.stl" scale="0.001 0.001 0.001"/>
    </geometry>
  </collision>
</link>

<joint name="Rev1" type="continuous">
  <origin rpy="0 0 0" xyz="0.0 0.0 0.07025"/>
  <parent link="base_link"/>
  <child link="shoulder_link_1_1"/>
  <axis xyz="0.0 0.0 1.0"/>
</joint>

<joint name="Rev2" type="revolute">
  <origin rpy="0 0 0" xyz="-0.044191 -0.011841 0.0336"/>
  <parent link="shoulder_link_1_1"/>
  <child link="upper_link_1"/>
  <axis xyz="-0.965926 -0.258819 -0.0"/>
  <limit effort="100" lower="-0.785398" upper="3.054326" velocity="100"/>
</joint>

<joint name="Rev3" type="revolute">
  <origin rpy="0 0 0" xyz="0.109498 -0.05512 0.035194"/>
  <parent link="upper_link_1"/>
  <child link="lower_link_1_1"/>
  <axis xyz="0.965926 0.258819 0.0"/>
  <limit effort="100" lower="-0.610865" upper="2.96706" velocity="100"/>
</joint>

<joint name="Rev4" type="continuous">
  <origin rpy="0 0 0" xyz="-0.044191 -0.011841 0.11025"/>
  <parent link="lower_link_1_1"/>
  <child link="shoulder_link_2_1"/>
  <axis xyz="0.0 -0.0 -1.0"/>
</joint>

<joint name="Rev5" type="revolute">
  <origin rpy="0 0 0" xyz="-0.022875 0.03962 0.0336"/>
  <parent link="shoulder_link_2_1"/>
  <child link="lower_link_2_1"/>
  <axis xyz="-0.5 0.866025 -0.0"/>
  <limit effort="100" lower="-0.610865" upper="2.879793" velocity="100"/>
</joint>

<joint name="Rev7" type="continuous">
  <origin rpy="0 0 0" xyz="-0.063659 -0.089581 0.046594"/>
  <parent link="lower_link_2_1"/>
  <child link="Plate_link_simp_v1_1"/>
  <axis xyz="0.784886 0.453154 -0.422618"/>
</joint>

</robot>
