<?xml version="1.0" ?>
<robot name="Proto" xmlns:xacro="http://www.ros.org/wiki/xacro">

<xacro:include filename="$(find Proto_description)/urdf/materials.xacro" />
<xacro:include filename="$(find Proto_description)/urdf/Proto.trans" />
<xacro:include filename="$(find Proto_description)/urdf/Proto.gazebo" />
<link name="base_link">
  <inertial>
    <origin rpy="0 0 0" xyz="0.0007396603431784532 0.03876764865079532 -8.191333003035142e-05"/>
    <mass value="0.2761464007003608"/>
    <inertia ixx="0.000757" ixy="-4e-06" ixz="-0.0" iyy="0.001272" iyz="-0.0" izz="0.000761"/>
  </inertial>
  <visual>
    <origin rpy="0 0 0" xyz="0 0 0"/>
    <geometry>
      <mesh filename="package://Proto_description/meshes/base_link.stl" scale="0.001 0.001 0.001"/>
    </geometry>
    <material name="silver"/>
  </visual>
  <collision>
    <origin rpy="0 0 0" xyz="0 0 0"/>
    <geometry>
      <mesh filename="package://Proto_description/meshes/base_link.stl" scale="0.001 0.001 0.001"/>
    </geometry>
  </collision>
</link>

<link name="Shoulder_link_v1_1">
  <inertial>
    <origin rpy="0 0 0" xyz="0.0011476357530529047 0.036700053149904696 -0.0013257537103132854"/>
    <mass value="0.19813823002340522"/>
    <inertia ixx="0.0001" ixy="1e-06" ixz="-2e-06" iyy="0.00013" iyz="2e-06" izz="0.000138"/>
  </inertial>
  <visual>
    <origin rpy="0 0 0" xyz="0.0 -0.072416 9.4e-05"/>
    <geometry>
      <mesh filename="package://Proto_description/meshes/Shoulder_link_v1_1.stl" scale="0.001 0.001 0.001"/>
    </geometry>
    <material name="silver"/>
  </visual>
  <collision>
    <origin rpy="0 0 0" xyz="0.0 -0.072416 9.4e-05"/>
    <geometry>
      <mesh filename="package://Proto_description/meshes/Shoulder_link_v1_1.stl" scale="0.001 0.001 0.001"/>
    </geometry>
  </collision>
</link>

<link name="Short_link_v1_1">
  <inertial>
    <origin rpy="0 0 0" xyz="-0.05563727015166487 0.030359599967377346 -0.05590123720325904"/>
    <mass value="0.2810513090866386"/>
    <inertia ixx="0.000386" ixy="4e-06" ixz="-2e-06" iyy="0.000487" iyz="9.4e-05" izz="0.000345"/>
  </inertial>
  <visual>
    <origin rpy="0 0 0" xyz="-0.045255 -0.110466 0.006454"/>
    <geometry>
      <mesh filename="package://Proto_description/meshes/Short_link_v1_1.stl" scale="0.001 0.001 0.001"/>
    </geometry>
    <material name="silver"/>
  </visual>
  <collision>
    <origin rpy="0 0 0" xyz="-0.045255 -0.110466 0.006454"/>
    <geometry>
      <mesh filename="package://Proto_description/meshes/Short_link_v1_1.stl" scale="0.001 0.001 0.001"/>
    </geometry>
  </collision>
</link>

<link name="Long_link_v1_1">
  <inertial>
    <origin rpy="0 0 0" xyz="0.046691605858878785 0.07135735168052673 -0.0017377276229717936"/>
    <mass value="0.2311934009151251"/>
    <inertia ixx="0.00038" ixy="8e-06" ixz="1.9e-05" iyy="0.000243" iyz="-2.2e-05" izz="0.000505"/>
  </inertial>
  <visual>
    <origin rpy="0 0 0" xyz="0.056505 -0.147994 0.073424"/>
    <geometry>
      <mesh filename="package://Proto_description/meshes/Long_link_v1_1.stl" scale="0.001 0.001 0.001"/>
    </geometry>
    <material name="silver"/>
  </visual>
  <collision>
    <origin rpy="0 0 0" xyz="0.056505 -0.147994 0.073424"/>
    <geometry>
      <mesh filename="package://Proto_description/meshes/Long_link_v1_1.stl" scale="0.001 0.001 0.001"/>
    </geometry>
  </collision>
</link>

<link name="Shoulder_link_v1__1__1">
  <inertial>
    <origin rpy="0 0 0" xyz="0.001756405463093377 0.03659132184255115 0.002826605655859113"/>
    <mass value="0.19813823002340522"/>
    <inertia ixx="0.000138" ixy="-1e-06" ixz="-4e-06" iyy="0.00013" iyz="3e-06" izz="0.0001"/>
  </inertial>
  <visual>
    <origin rpy="0 0 0" xyz="0.010398 -0.258093 0.074077"/>
    <geometry>
      <mesh filename="package://Proto_description/meshes/Shoulder_link_v1__1__1.stl" scale="0.001 0.001 0.001"/>
    </geometry>
    <material name="silver"/>
  </visual>
  <collision>
    <origin rpy="0 0 0" xyz="0.010398 -0.258093 0.074077"/>
    <geometry>
      <mesh filename="package://Proto_description/meshes/Shoulder_link_v1__1__1.stl" scale="0.001 0.001 0.001"/>
    </geometry>
  </collision>
</link>

<link name="Long_link_v1__1__1">
  <inertial>
    <origin rpy="0 0 0" xyz="0.04995397852609289 0.029894665405796883 -0.062337393213701034"/>
    <mass value="0.2311934009151251"/>
    <inertia ixx="0.00028" ixy="-8.8e-05" ixz="1.5e-05" iyy="0.000472" iyz="2.8e-05" izz="0.000377"/>
  </inertial>
  <visual>
    <origin rpy="0 0 0" xyz="-0.003232 -0.293729 0.028463"/>
    <geometry>
      <mesh filename="package://Proto_description/meshes/Long_link_v1__1__1.stl" scale="0.001 0.001 0.001"/>
    </geometry>
    <material name="silver"/>
  </visual>
  <collision>
    <origin rpy="0 0 0" xyz="-0.003232 -0.293729 0.028463"/>
    <geometry>
      <mesh filename="package://Proto_description/meshes/Long_link_v1__1__1.stl" scale="0.001 0.001 0.001"/>
    </geometry>
  </collision>
</link>

<link name="Plate_link_v1_1">
  <inertial>
    <origin rpy="0 0 0" xyz="0.008993855210408241 -0.0005342156687411226 -0.0034196496746962957"/>
    <mass value="0.014389707710093135"/>
    <inertia ixx="5e-06" ixy="1e-06" ixz="-0.0" iyy="3e-06" iyz="-0.0" izz="3e-06"/>
  </inertial>
  <visual>
    <origin rpy="0 0 0" xyz="-0.087233 -0.339943 0.09957"/>
    <geometry>
      <mesh filename="package://Proto_description/meshes/Plate_link_v1_1.stl" scale="0.001 0.001 0.001"/>
    </geometry>
    <material name="silver"/>
  </visual>
  <collision>
    <origin rpy="0 0 0" xyz="-0.087233 -0.339943 0.09957"/>
    <geometry>
      <mesh filename="package://Proto_description/meshes/Plate_link_v1_1.stl" scale="0.001 0.001 0.001"/>
    </geometry>
  </collision>
</link>

<joint name="Rev1" type="continuous">
  <origin rpy="0 0 0" xyz="0.0 0.072416 -9.4e-05"/>
  <parent link="base_link"/>
  <child link="Shoulder_link_v1_1"/>
  <axis xyz="-0.0 1.0 0.0"/>
</joint>

<joint name="Rev2" type="continuous">
  <origin rpy="0 0 0" xyz="0.045255 0.03805 -0.00636"/>
  <parent link="Shoulder_link_v1_1"/>
  <child link="Short_link_v1_1"/>
  <axis xyz="-0.990268 -0.0 0.139173"/>
</joint>

<joint name="Rev3" type="continuous">
  <origin rpy="0 0 0" xyz="-0.10176 0.037528 -0.06697"/>
  <parent link="Short_link_v1_1"/>
  <child link="Long_link_v1_1"/>
  <axis xyz="0.990268 0.0 -0.139173"/>
</joint>

<joint name="Rev4" type="continuous">
  <origin rpy="0 0 0" xyz="0.046107 0.110099 -0.000653"/>
  <parent link="Long_link_v1_1"/>
  <child link="Shoulder_link_v1__1__1"/>
  <axis xyz="0.007284 0.99863 0.051827"/>
</joint>

<joint name="Rev5" type="continuous">
  <origin rpy="0 0 0" xyz="0.01363 0.035636 0.045614"/>
  <parent link="Shoulder_link_v1__1__1"/>
  <child link="Long_link_v1__1__1"/>
  <axis xyz="-0.292183 0.051692 -0.954964"/>
</joint>

<joint name="Rev6" type="continuous">
  <origin rpy="0 0 0" xyz="0.084001 0.046214 -0.071107"/>
  <parent link="Long_link_v1__1__1"/>
  <child link="Plate_link_v1_1"/>
  <axis xyz="0.883157 0.397732 -0.248684"/>
</joint>

</robot>
