<?xml version="1.0" ?>
<robot name="proto" xmlns:xacro="http://www.ros.org/wiki/xacro">

<xacro:include filename="$(find proto_description)/urdf/materials.xacro" />
<xacro:include filename="$(find proto_description)/urdf/proto.trans" />
<xacro:include filename="$(find proto_description)/urdf/proto.gazebo" />
<link name="base_link">
  <inertial>
    <origin rpy="0 0 0" xyz="0.0007396603431815715 -1.2109763603965092e-05 0.03660197662963566"/>
    <mass value="0.2761464007003995"/>
    <inertia ixx="0.000757" ixy="0.0" ixz="-4e-06" iyy="0.000761" iyz="0.0" izz="0.001272"/>
  </inertial>
  <visual>
    <origin rpy="0 0 0" xyz="0 0 0"/>
    <geometry>
      <mesh filename="package://proto_description/meshes/base_link.stl" scale="0.001 0.001 0.001"/>
    </geometry>
    <material name="silver"/>
  </visual>
  <collision>
    <origin rpy="0 0 0" xyz="0 0 0"/>
    <geometry>
      <mesh filename="package://proto_description/meshes/base_link.stl" scale="0.001 0.001 0.001"/>
    </geometry>
  </collision>
</link>

<link name="Shoulder_link_v1_1">
  <inertial>
    <origin rpy="0 0 0" xyz="0.0011476357530529548 0.0013257306166784657 0.036700381128999024"/>
    <mass value="0.19813823002340522"/>
    <inertia ixx="0.0001" ixy="2e-06" ixz="1e-06" iyy="0.000138" iyz="-2e-06" izz="0.00013"/>
  </inertial>
  <visual>
    <origin rpy="0 0 0" xyz="-0.0 0.0 -0.07025"/>
    <geometry>
      <mesh filename="package://proto_description/meshes/Shoulder_link_v1_1.stl" scale="0.001 0.001 0.001"/>
    </geometry>
    <material name="silver"/>
  </visual>
  <collision>
    <origin rpy="0 0 0" xyz="-0.0 0.0 -0.07025"/>
    <geometry>
      <mesh filename="package://proto_description/meshes/Shoulder_link_v1_1.stl" scale="0.001 0.001 0.001"/>
    </geometry>
  </collision>
</link>

<link name="Short_link_v1_1">
  <inertial>
    <origin rpy="0 0 0" xyz="0.0258118102689577 0.06734796603991125 0.030359927946473478"/>
    <mass value="0.2810513090866386"/>
    <inertia ixx="0.000386" ixy="2e-06" ixz="4e-06" iyy="0.000345" iyz="-9.4e-05" izz="0.000487"/>
  </inertial>
  <visual>
    <origin rpy="0 0 0" xyz="0.035897 0.005045 -0.1083"/>
    <geometry>
      <mesh filename="package://proto_description/meshes/Short_link_v1_1.stl" scale="0.001 0.001 0.001"/>
    </geometry>
    <material name="silver"/>
  </visual>
  <collision>
    <origin rpy="0 0 0" xyz="0.035897 0.005045 -0.1083"/>
    <geometry>
      <mesh filename="package://proto_description/meshes/Short_link_v1_1.stl" scale="0.001 0.001 0.001"/>
    </geometry>
  </collision>
</link>

<link name="Long_link_v1_1">
  <inertial>
    <origin rpy="0 0 0" xyz="0.04617094632274027 0.00544238962844841 0.0715089075148111"/>
    <mass value="0.2311934009151251"/>
    <inertia ixx="0.00038" ixy="-1.8e-05" ixz="1e-05" iyy="0.000507" iyz="8e-06" izz="0.000242"/>
  </inertial>
  <visual>
    <origin rpy="0 0 0" xyz="0.056505 -0.07333 -0.145829"/>
    <geometry>
      <mesh filename="package://proto_description/meshes/Long_link_v1_1.stl" scale="0.001 0.001 0.001"/>
    </geometry>
    <material name="silver"/>
  </visual>
  <collision>
    <origin rpy="0 0 0" xyz="0.056505 -0.07333 -0.145829"/>
    <geometry>
      <mesh filename="package://proto_description/meshes/Long_link_v1_1.stl" scale="0.001 0.001 0.001"/>
    </geometry>
  </collision>
</link>

<link name="Shoulder_link_v1__1__1">
  <inertial>
    <origin rpy="0 0 0" xyz="0.0014892689929757522 -0.0009262121111986016 0.03669988277157421"/>
    <mass value="0.19813823002340522"/>
    <inertia ixx="0.000138" ixy="4e-06" ixz="-2e-06" iyy="0.0001" iyz="-1e-06" izz="0.00013"/>
  </inertial>
  <visual>
    <origin rpy="0 0 0" xyz="0.011201 -0.079697 -0.256079"/>
    <geometry>
      <mesh filename="package://proto_description/meshes/Shoulder_link_v1__1__1.stl" scale="0.001 0.001 0.001"/>
    </geometry>
    <material name="silver"/>
  </visual>
  <collision>
    <origin rpy="0 0 0" xyz="0.011201 -0.079697 -0.256079"/>
    <geometry>
      <mesh filename="package://proto_description/meshes/Shoulder_link_v1__1__1.stl" scale="0.001 0.001 0.001"/>
    </geometry>
  </collision>
</link>

<link name="Long_link_v1__1__1">
  <inertial>
    <origin rpy="0 0 0" xyz="0.04880754986945039 0.06352496495431187 0.029281632440641747"/>
    <mass value="0.2311934009151251"/>
    <inertia ixx="0.000287" ixy="-1.8e-05" ixz="-9.5e-05" iyy="0.000375" iyz="-2.5e-05" izz="0.000466"/>
  </inertial>
  <visual>
    <origin rpy="0 0 0" xyz="-0.002248 -0.035707 -0.294129"/>
    <geometry>
      <mesh filename="package://proto_description/meshes/Long_link_v1__1__1.stl" scale="0.001 0.001 0.001"/>
    </geometry>
    <material name="silver"/>
  </visual>
  <collision>
    <origin rpy="0 0 0" xyz="-0.002248 -0.035707 -0.294129"/>
    <geometry>
      <mesh filename="package://proto_description/meshes/Long_link_v1__1__1.stl" scale="0.001 0.001 0.001"/>
    </geometry>
  </collision>
</link>

<link name="Plate_link_v1_1">
  <inertial>
    <origin rpy="0 0 0" xyz="0.00901400403018704 0.003393472892842142 -0.00031020971946160714"/>
    <mass value="0.014389707710093135"/>
    <inertia ixx="5e-06" ixy="1e-06" ixz="1e-06" iyy="3e-06" iyz="0.0" izz="4e-06"/>
  </inertial>
  <visual>
    <origin rpy="0 0 0" xyz="-0.084427 -0.108672 -0.340722"/>
    <geometry>
      <mesh filename="package://proto_description/meshes/Plate_link_v1_1.stl" scale="0.001 0.001 0.001"/>
    </geometry>
    <material name="silver"/>
  </visual>
  <collision>
    <origin rpy="0 0 0" xyz="-0.084427 -0.108672 -0.340722"/>
    <geometry>
      <mesh filename="package://proto_description/meshes/Plate_link_v1_1.stl" scale="0.001 0.001 0.001"/>
    </geometry>
  </collision>
</link>

<joint name="Rev1" type="continuous">
  <origin rpy="0 0 0" xyz="0.0 0.0 0.07025"/>
  <parent link="base_link"/>
  <child link="Shoulder_link_v1_1"/>
  <axis xyz="0.0 0.0 1.0"/>
</joint>

<joint name="Rev2" type="continuous">
  <origin rpy="0 0 0" xyz="-0.035897 -0.005045 0.03805"/>
  <parent link="Shoulder_link_v1_1"/>
  <child link="Short_link_v1_1"/>
  <axis xyz="-0.990268 -0.139173 0.0"/>
</joint>

<joint name="Rev3" type="continuous">
  <origin rpy="0 0 0" xyz="-0.020608 0.078375 0.037529"/>
  <parent link="Short_link_v1_1"/>
  <child link="Long_link_v1_1"/>
  <axis xyz="0.990268 0.139173 -0.0"/>
</joint>

<joint name="Rev4" type="continuous">
  <origin rpy="0 0 0" xyz="0.045304 0.006367 0.11025"/>
  <parent link="Long_link_v1_1"/>
  <child link="Shoulder_link_v1__1__1"/>
  <axis xyz="0.0 -0.0 1.0"/>
</joint>

<joint name="Rev5" type="continuous">
  <origin rpy="0 0 0" xyz="0.013449 -0.04399 0.03805"/>
  <parent link="Shoulder_link_v1__1__1"/>
  <child link="Long_link_v1__1__1"/>
  <axis xyz="-0.292372 0.956305 0.0"/>
</joint>

<joint name="Rev6" type="continuous">
  <origin rpy="0 0 0" xyz="0.082179 0.072965 0.046593"/>
  <parent link="Long_link_v1__1__1"/>
  <child link="Plate_link_v1_1"/>
  <axis xyz="0.866706 0.264979 0.422618"/>
</joint>

</robot>
